Workbook

Sheet Сверка цен
A1: № | B1: Позиция | C1: Ед. | D1: Смета: диапазон (Хаб.) | E1: Рынок мин | F1: Рынок макс | G1: Рынок средняя | H1: Отклонение средней от середины сметы | I1: Аренда/мес, средняя | J1: Смета: аренда/мес | K1: НДС | L1: Доставка / монтаж / подача | M1: Источники | N1: Дата | O1: Допущение? | P1: Вывод
A2: ТРАНСПОРТ И СПЕЦТЕХНИКА (аренда с оператором, смена 8 ч)
A3: 1 | B3: Бульдозер Т-130/Shantui SD16/D65 | C3: смена | D3: 12 000 - 18 000 ₽ | E3: 15200 | F3: 28000 | G3: 24000 | H3: 0.6 | I3: 420000 | J3: от 300 000 ₽ | K3: частники без НДС; buldozer-khabarovsk, Arena27 — с НДС | L3: трал отдельно 15–25 тыс./рейс | M3: perevozka24.com/habarovsk-27 (SD16 1900 ₽/ч, Т-170 3500 ₽/ч); stroitaxi.ru (от 2500 ₽/ч); exkavator.ru (D6R 2200 ₽/ч); farpost (от 2500 ₽/ч) | N3: 20.10.2026 | P3: Занижено: смена на 30–35%, месяц на 25–35%
A4: 2 | B4: Экскаватор гусеничный 0,5 м³ | C4: смена | D4: 16 000 - 22 000 ₽ | E4: 13600 | F4: 20000 | G4: 16000 | H4: -0.15789474 | I4: 310000 | J4: от 350 000 ₽ | K4: в осн. без НДС | L4: трал обязателен 10–17 тыс. | M4: uslugi.yandex.ru (PC-128 1700 ₽/ч); perevozka24 (SK100W 16 000/смена, EX100 16 000/смена); ecorex (от 1900 ₽/ч) | N4: 20.10.2026 | P4: Верх смены и месяц слегка завышены
A5: 3 | B5: Экскаватор-погрузчик JCB 3CX | C5: смена | D5: 18 000 - 23 000 ₽ | E5: 20000 | F5: 28000 | G5: 23000 | H5: 0.12195122 | I5: 440000 | J5: от 400 000 ₽ | K5: частники без НДС; есть с НДС 3500 ₽/ч | L5: своим ходом | M5: arena27.ru (2500 ₽/ч, мин 4 ч); uslugi.yandex.ru (от 36–40 тыс./день); farpost (2800–3500 ₽/ч) | N5: 20.10.2026 | P5: Смена в рынке, месяц занижен на 5–10%
A6: 4 | B6: Мини-погрузчик Bobcat S630 (аналоги S300/643) | C6: смена | D6: 12 000 - 16 000 ₽ | E6: 8000 | F6: 16000 | G6: 12000 | H6: -0.14285714 | I6: 240000 | J6: от 280 000 ₽ | K6: без НДС | L6: доставка ~4000 ₽ | M6: uslugi.yandex.ru (S300 от 1000, 643 от 1500 ₽/ч); perevozka24 (1000 ₽/ч; 13 000/смена) | N6: 20.10.2026 | O6: ДА | P6: Завышено: верх смены ~15%, месяц 10–30%
A7: 5 | B7: Самосвал КАМАЗ до 15 т | C7: смена | D7: 9 000 - 14 000 ₽ | E7: 12000 | F7: 22400 | G7: 17000 | H7: 0.47826087 | I7: 300000 | J7: от 280 000 ₽ | K7: без НДС; ДЭСК — юрлицо | L7: дорога ≥1 ч | M7: perevozka24 (1500–2000 ₽/ч); uslugi.yandex.ru (ДЭСК 2800 ₽/ч, мин 8 ч; Тонар от 1500) | N7: 20.10.2026 | P7: Занижено: смена на 20–40%
A8: 6 | B8: Манипулятор 5–7 т | C8: смена | D8: 18 000 - 25 000 ₽ | E8: 16000 | F8: 32000 | G8: 22000 | H8: 0.023255814 | I8: 400000 | J8: от 380 000 ₽ | K8: без НДС | L8: мин 2 ч | M8: perevozka24 (2000–3500 ₽/ч; 30–32 тыс./смена); uslugi.yandex.ru (1500–4500 ₽/ч) | N8: 20.10.2026 | P8: В рынке
A9: 7 | B9: Автовышка 18 м | C9: смена | D9: 18 000 - 24 000 ₽ | E9: 14000 | F9: 24000 | G9: 16500 | H9: -0.21428571 | I9: 320000 | J9: от 380 000 ₽ | K9: без НДС | L9: мин 3–4 ч с дорогой | M9: stroitaxi.ru (18 м от 1800 ₽/ч); perevozka24 (14–21 тыс./смена); uslugi.yandex.ru (от 1700 ₽/ч) | N9: 20.10.2026 | P9: Завышено: смена 10–25%, месяц 15–25%
A10: 8 | B10: Тягач + полуприцеп/трал | C10: смена | D10: 16 000 - 22 000 ₽ | E10: 14500 | F10: 25000 | G10: 18000 | H10: -0.052631579 | I10: 340000 | J10: от 280 000 ₽ | K10: без НДС | L10: межгород 50–200 ₽/км | M10: perevozka24 (14 500–25 000/смена); uslugi.yandex.ru (трал от 2400 ₽/ч); stroitaxi (от 10 000 за услугу) | N10: 20.10.2026 | O10: ДА | P10: Смена в рынке, месяц занижен 15–25%
A11: 9 | B11: Бортовой автомобиль до 5 т | C11: смена | D11: 7 000 - 10 000 ₽ | E11: 10400 | F11: 13600 | G11: 11600 | H11: 0.36470588 | I11: 220000 | J11: от 170 000 ₽ | K11: без НДС | L11: мин 2 ч | M11: perevozka24 (Hino 5 т 1300 ₽/ч); gruz27.ru (1700 ₽/ч); uslugi.yandex.ru (1350–1500 ₽/ч) | N11: 20.10.2026 | P11: Занижено: смена 15–30%, месяц 20–35%
A12: 10 | B12: Автокран 16 т (Ивановец) | C12: смена | D12: 20 000 - 28 000 ₽ | E12: 16000 | F12: 32000 | G12: 22500 | H12: -0.0625 | I12: 420000 | J12: от 400 000 ₽ | K12: без НДС | L12: мин 3–4 ч | M12: uslugi.yandex.ru (до 15 т от 2500 ₽/ч); farpost (от 3000 ₽/ч); perevozka24 (25 т 24 000/смена) | N12: 20.10.2026 | P12: В рынке
A13: 11 | B13: Компрессор дизельный ~5 м³/мин | C13: смена | D13: 6 000 - 10 000 ₽ | E13: 4000 | F13: 17600 | G13: 6500 | H13: -0.1875 | I13: 110000 | J13: от 130 000 ₽ | K13: прокаты — безнал с НДС | L13: буксир, доставка от 200 ₽ | M13: stroika-arenda (XAS 97 4000 ₽/сут); стахановец.рф (DACS-3 4000–5000); perevozka24 (900–2200 ₽/ч с оператором) | N13: 20.10.2026 | O13: ДА | P13: Смена в рынке, месяц слегка завышен
A14: 12 | B14: Отбойный молоток пневматический | C14: смена | D14: 1 200 - 2 000 ₽ | E14: 900 | F14: 2500 | G14: 1500 | H14: -0.0625 | I14: 35000 | J14: от 20 000 ₽ | K14: есть с НДС | L14: доставка от 300 ₽ | M14: arenda-dv.ru (МОП-3 от 900); стахановец.рф (2100–2500); stroika-arenda (эл. 700–1600) | N14: 20.10.2026 | P14: Смена в рынке; месяц в смете ЗАНИЖЕН (реально 30–40 тыс.)
A15: 13 | B15: Пост газосварки/резки (без газов) | C15: смена | D15: 1 800 - 3 000 ₽ | E15: 400 | F15: 900 | G15: 600 | H15: -0.75 | I15: 15000 | J15: от 30 000 ₽ | K15: безнал есть | L15: 150–300 ₽ | M15: stroika-arenda (ПГУ-10П от 600, резак 400); arenda-dv (900–1800 с баллонами) | N15: 20.10.2026 | P15: ЗАВЫШЕНО ~в 3 раза
A16: 14 | B16: Сварочный аппарат до 350 А | C16: смена | D16: 800 - 1 500 ₽ | E16: 500 | F16: 900 | G16: 700 | H16: -0.39130435 | I16: 17000 | J16: от 15 000 ₽ | K16: безнал есть | L16: 150–300 ₽ | M16: стахановец.рф (ARC 315 600–800); 2gis Прокат-сервис (700); stroika-arenda (от 500) | N16: 20.10.2026 | P16: В рынке / чуть выше
A17: 15 | B17: Каток грунтовый 16–20 т (30 т в Хабаровске нет) | C17: смена | D17: 14 000 - 20 000 ₽ | E17: 15200 | F17: 22400 | G17: 19000 | H17: 0.11764706 | I17: 370000 | J17: от 350 000 ₽ | K17: частники без НДС | L17: трал отдельно | M17: perevozka24 (SR16 1900–2500 ₽/ч, 20 т 2400–2800 ₽/ч); borg-pro.ru (18 т от 1900 ₽/ч) | N17: 20.10.2026 | O17: ДА | P17: В рынке (класс заменён)
A18: 16 | B18: Бункер 8–20 м³ (установка+вывоз) | C18: вывоз | D18: 4 000 - 9 000 ₽ | E18: 3200 | F18: 9500 | G18: 5500 | H18: -0.15384615 | I18: 55000 | J18: от 60 000 ₽ | K18: без НДС | L18: погрузка 1200–7000 ₽ отдельно | M18: perevozka24 (8 м³ 3600–9500, 20 м³ 7500, 27 м³ 7500–8500); myguru (8 м³ от 3200, 20 м³ от 5700) | N18: 20.10.2026 | P18: В рынке
A19: 17 | B19: Полигон — приём отходов | C19: т | D19: 600 - 1 800 ₽ | E19: 798 | F19: 1500 | G19: 1100 | H19: -0.083333333 | K19: тариф без НДС (798,41) | L19: через ПС «Северная» | M19: Постановление КЦТ Хаб. края 26.11.2025 №40/46 (АО «Спецавтохозяйство», 798,41 ₽/т на 2026); abak27.ru (от 1500 ₽/м³) | N19: 20.10.2026 | P19: Низ ниже тарифа, верх завышен; реально 800–1300
A20: РАСХОДНЫЕ МАТЕРИАЛЫ
A21: 18 | B21: Ацетилен 40 л — заправка/обмен | C21: баллон | D21: 5 000 - 7 500 ₽ | E21: 5500 | F21: 13010 | G21: 7000 | H21: 0.12 | K21: станция — НДС 5% вкл. | L21: не вкл. | M21: stgdv.ru прайс 18.02.2026 (5600–7620, Комсомольск); vdsdv.ru Хабаровск (13 010); bizorg (5500) | N21: 20.10.2026 | P21: В рынке как заправка. Покупка с баллоном = 26–45 тыс. (смета занижена в 4–6 раз)
A22: 19 | B22: Пропан-бутан 50 л — заправка | C22: баллон | D22: 2 000 - 2 800 ₽ | E22: 1450 | F22: 2900 | G22: 2400 | H22: 0 | K22: НДС вкл. | L22: у «Эко-Газ» включена | M22: vdsdv.ru (2260); stgdv.ru (2760); эко-газ.рф (2900 с доставкой) | N22: 20.10.2026 | P22: В рынке
A23: 20 | B23: Кислород 40 л (6 м³) — заправка | C23: баллон | D23: 900 - 1 500 ₽ | E23: 700 | F23: 1350 | G23: 900 | H23: -0.25 | K23: НДС вкл. | L23: не вкл. | M23: stgdv.ru (760–780); vdsdv.ru (1350); kislorod-servis (700) | N23: 20.10.2026 | P23: Верх 1500 слегка завышен
A24: 21 | B24: Бензин АИ-95 (АИ-98 = 88,72 ₽) | C24: л | D24: 73 - 88 ₽ | E24: 75.69 | F24: 78.25 | G24: 75.7 | H24: -0.059627329 | K24: розница, вкл. | L24: — | M24: fuelprice.ru/t-habarovsk, 17–20.10.2026 (ННК 75,69; Роснефть 75,75–75,80; АИ-98 88,72) | N24: 20.10.2026 | P24: Низ 73 ниже рынка
A25: 22 | B25: Масло 2Т | C25: л | D25: 460 - 850 ₽ | E25: 342 | F25: 800 | G25: 520 | H25: -0.20610687 | K25: вкл. | L25: — | M25: hatar.ru Хабаровск (430–680); lemanapro Хабаровск (342–650); skatpower (470) | N25: 20.10.2026 | P25: В рынке
A26: 23 | B26: Масло цепное | C26: л | D26: 1 000 - 1 500 ₽ | E26: 250 | F26: 700 | G26: 480 | H26: -0.616 | K26: вкл. | L26: — | M26: lemanapro.ru (231–700); vseinstrumenti (368–429); husq.ru (1290–1490 — бренд) | N26: 20.10.2026 | O26: ДА | P26: ЗАВЫШЕНО в 2–3 раза (если не фирменное)
A27: СТРОИТЕЛЬНЫЕ МАТЕРИАЛЫ
A28: 24 | B28: Песок строительный II кл. (с доставкой) | C28: м³ | D28: 500 - 1 300 ₽ | E28: 500 | F28: 1280 | G28: 900 | H28: 0 | K28: НДС не указан | L28: вкл. в 900 (Виноградовка) | M28: amurcement.ru (730–760 + доставка от 1000); песоквхабаровске.рф (500 самовывоз / 900 с дост.); perevozka24 | N28: 20.10.2026 | P28: В рынке
A29: 25 | B29: Щебень гранитный крупный (80-120 нет; между 40-70 и 100-200) | C29: м³ | D29: 2 000 - 4 100 ₽ | E29: 1891 | F29: 3000 | G29: 2600 | H29: -0.14754098 | K29: вкл. 22% | L29: самовывоз ~2100; доставка +500–900 | M29: Корфовский каменный карьер, прайс с 01.02.2026 (40-70 1891, 100-200 2318 с НДС) aokkk.ru | N29: 20.10.2026 | O29: ДА | P29: Верх 4100 — только при дальней доставке
A30: 26 | B30: Щебень 20-40 | C30: м³ | D30: 1 990 - 2 800 ₽ | E30: 1952 | F30: 2800 | G30: 2300 | H30: -0.039665971 | K30: вкл. 22% | L30: +600–900 ₽/м³ | M30: Корфовский карьер (1952 с НДС, 01.02.2026); regtorg | N30: 20.10.2026 | P30: В рынке
A31: 27 | B31: Грунт растительный (навал с доставкой) | C31: м³ | D31: 500 - 2 500 ₽ | E31: 600 | F31: 1300 | G31: 800 | H31: -0.46666667 | K31: н/д | L31: рейс 6500–9500 | M31: ekogrunt-khv.ru (от 650; биг-бэг 2500); regtorg (599–1300) | N31: 20.10.2026 | P31: Верх 2500 — только биг-бэги
A32: 28 | B32: Вода техническая (водовоз) | C32: м³ | D32: 400 - 700 ₽ | E32: 500 | F32: 700 | G32: 600 | H32: 0.090909091 | K32: н/д | L32: вкл. | M32: perevozka24 (500–700); uslugi.yandex.ru (от 1500/заказ) | N32: 20.10.2026 | P32: В рынке
A33: 29 | B33: Асфальтобетон горячий тип А/Б (ЩМА ~8 500–9 000) | C33: т | D33: 3 400 - 7 000 ₽ | E33: 6300 | F33: 9000 | G33: 7000 | H33: 0.34615385 | K33: вероятно вкл. | L33: самосвал 25 т — 14 000/рейс | M33: 2gis «Дорожно-строительные материалы», прайс 30.04.2025 (А/Б 6500–6700, ЩМА 8300); пересчёт на 2026 +4–8% | N33: 20.10.2026 | O33: ДА | P33: Низ 3400 ЗАНИЖЕН почти вдвое
A34: 30 | B34: Катанка 6,3–6,5 мм | C34: т | D34: 80 000 - 91 000 ₽ | E34: 72000 | F34: 82000 | G34: 77000 | H34: -0.099415205 | K34: с НДС | L34: склад в Хабаровске | M34: Металлсервис Хабаровск, прайс price_hab.xls 20.10.2026 (А1 Ø6 78 590; катанки нет) | N34: 20.10.2026 | O34: ДА | P34: Слегка завышено
A35: 31 | B35: Лес круглый хвойный ø14–24 | C35: м³ | D35: 10 000 - 15 000 ₽ | E35: 3500 | F35: 8500 | G35: 6000 | H35: -0.52 | K35: н/д | L35: +1000–2500 | M35: gde.ru Хабаровск (3500); woodresource (лиственница 8500); berfi (3150–3500) | N35: 20.10.2026 | P35: ЗАВЫШЕНО в 1,5–2 раза
A36: 32 | B36: Брусок обрезной хвоя 1–2 с. | C36: м³ | D36: 18 000 - 24 000 ₽ | E36: 10500 | F36: 28000 | G36: 22000 | H36: 0.047619048 | K36: ДОК: оба варианта | L36: по городу | M36: docandrey.ru Андреевский ДОК (22 000–23 400 без НДС); gde.ru (10 500 ест. влажн.) | N36: 20.10.2026 | P36: В рынке
A37: 33 | B37: Доска обрезная 25 мм | C37: м³ | D37: 16 000 - 22 000 ₽ | E37: 9500 | F37: 22800 | G37: 18000 | H37: -0.052631579 | K37: ДОК: оба варианта | L37: по городу | M37: docandrey.ru (18 000–19 000); gde.ru (9500–10 500) | N37: 20.10.2026 | P37: В рынке
A38: 34 | B38: Геотекстиль 300 г/м² | C38: м² | D38: 31 - 90 ₽ | E38: 36 | F38: 147 | G38: 90 | H38: 0.48760331 | K38: н/д | L38: склады в Хабаровске | M38: promzapas Хабаровск (79–147); asc-khv.ru (100); uik-rus (от 36, опт) | N38: 20.10.2026 | P38: Низ 31 занижен
A39: 35 | B39: Камень бутовый 150–500 мм | C39: т | D39: 5 900 - 6 500 ₽ | E39: 1500 | F39: 3500 | G39: 2500 | H39: -0.59677419 | K39: — | L39: +500–1000 ₽/т | M39: Хабаровских цен нет; Корфовский карьер (тел. 4212 49-22-32); regtorg (другие города 600–2500) | N39: 20.10.2026 | O39: ДА | P39: ЗАВЫШЕНО в 2–3 раза
A40: 36 | B40: Плёнка ПЭ 200 мкм (500 мкм ≈ 60–90) | C40: м² | D40: 50 - 100 ₽ | E40: 20 | F40: 37 | G40: 30 | H40: -0.6 | K40: с НДС | L40: в городе | M40: khv-fanera.ru прайс 25.09.2026 (30,7 ₽/м²); техрегион Владивосток (36,7) | N40: 20.10.2026 | P40: ЗАВЫШЕНО в 2–3 раза для 200 мкм
...

Sheet Сценарий бульвара
A1: № | B1: Позиция | C1: Ед. | D1: Кол-во (ДОПУЩЕНИЕ — замените своим) | E1: Основание объёма | F1: Цена ед., средняя | G1: Множитель (работодатель ×1,5) | H1: Сумма, ₽ | I1: Сумма по мин., ₽ | J1: Сумма по макс., ₽
A2: ТРАНСПОРТ И СПЕЦТЕХНИКА (аренда с оператором, смена 8 ч)
A3: 1 | B3: Бульдозер Т-130/Shantui SD16/D65 | C3: смена | D3: 15 | E3: планировка, срезка | F3: ='Сверка цен'!G3 | G3: 1 | H3: =D3*F3*G3 | I3: =D3*'Сверка цен'!E3*G3 | J3: =D3*'Сверка цен'!F3*G3
A4: 2 | B4: Экскаватор гусеничный 0,5 м³ | C4: смена | D4: 30 | E4: котлованы, траншеи | F4: ='Сверка цен'!G4 | G4: 1 | H4: =D4*F4*G4 | I4: =D4*'Сверка цен'!E4*G4 | J4: =D4*'Сверка цен'!F4*G4
A5: 3 | B5: Экскаватор-погрузчик JCB 3CX | C5: смена | D5: 60 | E5: универсальная машина | F5: ='Сверка цен'!G5 | G5: 1 | H5: =D5*F5*G5 | I5: =D5*'Сверка цен'!E5*G5 | J5: =D5*'Сверка цен'!F5*G5
A6: 4 | B6: Мини-погрузчик Bobcat S630 (аналоги S300/643) | C6: смена | D6: 60 | E6: планировка, подача | F6: ='Сверка цен'!G6 | G6: 1 | H6: =D6*F6*G6 | I6: =D6*'Сверка цен'!E6*G6 | J6: =D6*'Сверка цен'!F6*G6
A7: 5 | B7: Самосвал КАМАЗ до 15 т | C7: смена | D7: 120 | E7: 2 машины × 60 смен | F7: ='Сверка цен'!G7 | G7: 1 | H7: =D7*F7*G7 | I7: =D7*'Сверка цен'!E7*G7 | J7: =D7*'Сверка цен'!F7*G7
A8: 6 | B8: Манипулятор 5–7 т | C8: смена | D8: 20 | E8: бордюр, опоры | F8: ='Сверка цен'!G8 | G8: 1 | H8: =D8*F8*G8 | I8: =D8*'Сверка цен'!E8*G8 | J8: =D8*'Сверка цен'!F8*G8
A9: 7 | B9: Автовышка 18 м | C9: смена | D9: 15 | E9: монтаж светильников | F9: ='Сверка цен'!G9 | G9: 1 | H9: =D9*F9*G9 | I9: =D9*'Сверка цен'!E9*G9 | J9: =D9*'Сверка цен'!F9*G9
A10: 8 | B10: Тягач + полуприцеп/трал | C10: смена | D10: 6 | E10: перебазировка техники | F10: ='Сверка цен'!G10 | G10: 1 | H10: =D10*F10*G10 | I10: =D10*'Сверка цен'!E10*G10 | J10: =D10*'Сверка цен'!F10*G10
A11: 9 | B11: Бортовой автомобиль до 5 т | C11: смена | D11: 40 | F11: ='Сверка цен'!G11 | G11: 1 | H11: =D11*F11*G11 | I11: =D11*'Сверка цен'!E11*G11 | J11: =D11*'Сверка цен'!F11*G11
A12: 10 | B12: Автокран 16 т (Ивановец) | C12: смена | D12: 15 | F12: ='Сверка цен'!G12 | G12: 1 | H12: =D12*F12*G12 | I12: =D12*'Сверка цен'!E12*G12 | J12: =D12*'Сверка цен'!F12*G12
A13: 11 | B13: Компрессор дизельный ~5 м³/мин | C13: смена | D13: 20 | E13: демонтаж | F13: ='Сверка цен'!G13 | G13: 1 | H13: =D13*F13*G13 | I13: =D13*'Сверка цен'!E13*G13 | J13: =D13*'Сверка цен'!F13*G13
A14: 12 | B14: Отбойный молоток пневматический | C14: смена | D14: 20 | F14: ='Сверка цен'!G14 | G14: 1 | H14: =D14*F14*G14 | I14: =D14*'Сверка цен'!E14*G14 | J14: =D14*'Сверка цен'!F14*G14
A15: 13 | B15: Пост газосварки/резки (без газов) | C15: смена | D15: 10 | F15: ='Сверка цен'!G15 | G15: 1 | H15: =D15*F15*G15 | I15: =D15*'Сверка цен'!E15*G15 | J15: =D15*'Сверка цен'!F15*G15
A16: 14 | B16: Сварочный аппарат до 350 А | C16: смена | D16: 30 | F16: ='Сверка цен'!G16 | G16: 1 | H16: =D16*F16*G16 | I16: =D16*'Сверка цен'!E16*G16 | J16: =D16*'Сверка цен'!F16*G16
A17: 15 | B17: Каток грунтовый 16–20 т (30 т в Хабаровске нет) | C17: смена | D17: 25 | F17: ='Сверка цен'!G17 | G17: 1 | H17: =D17*F17*G17 | I17: =D17*'Сверка цен'!E17*G17 | J17: =D17*'Сверка цен'!F17*G17
A18: 16 | B18: Бункер 8–20 м³ (установка+вывоз) | C18: вывоз | D18: 30 | F18: ='Сверка цен'!G18 | G18: 1 | H18: =D18*F18*G18 | I18: =D18*'Сверка цен'!E18*G18 | J18: =D18*'Сверка цен'!F18*G18
A19: 17 | B19: Полигон — приём отходов | C19: т | D19: 300 | E19: демонтаж старых покрытий | F19: ='Сверка цен'!G19 | G19: 1 | H19: =D19*F19*G19 | I19: =D19*'Сверка цен'!E19*G19 | J19: =D19*'Сверка цен'!F19*G19
A20: РАСХОДНЫЕ МАТЕРИАЛЫ
A21: 18 | B21: Ацетилен 40 л — заправка/обмен | C21: баллон | D21: 10 | F21: ='Сверка цен'!G21 | G21: 1 | H21: =D21*F21*G21 | I21: =D21*'Сверка цен'!E21*G21 | J21: =D21*'Сверка цен'!F21*G21
A22: 19 | B22: Пропан-бутан 50 л — заправка | C22: баллон | D22: 15 | F22: ='Сверка цен'!G22 | G22: 1 | H22: =D22*F22*G22 | I22: =D22*'Сверка цен'!E22*G22 | J22: =D22*'Сверка цен'!F22*G22
A23: 20 | B23: Кислород 40 л (6 м³) — заправка | C23: баллон | D23: 30 | F23: ='Сверка цен'!G23 | G23: 1 | H23: =D23*F23*G23 | I23: =D23*'Сверка цен'!E23*G23 | J23: =D23*'Сверка цен'!F23*G23
A24: 21 | B24: Бензин АИ-95 (АИ-98 = 88,72 ₽) | C24: л | D24: 2000 | F24: ='Сверка цен'!G24 | G24: 1 | H24: =D24*F24*G24 | I24: =D24*'Сверка цен'!E24*G24 | J24: =D24*'Сверка цен'!F24*G24
A25: 22 | B25: Масло 2Т | C25: л | D25: 40 | F25: ='Сверка цен'!G25 | G25: 1 | H25: =D25*F25*G25 | I25: =D25*'Сверка цен'!E25*G25 | J25: =D25*'Сверка цен'!F25*G25
A26: 23 | B26: Масло цепное | C26: л | D26: 20 | F26: ='Сверка цен'!G26 | G26: 1 | H26: =D26*F26*G26 | I26: =D26*'Сверка цен'!E26*G26 | J26: =D26*'Сверка цен'!F26*G26
A27: СТРОИТЕЛЬНЫЕ МАТЕРИАЛЫ
A28: 24 | B28: Песок строительный II кл. (с доставкой) | C28: м³ | D28: 650 | E28: основания 4100 м² × 0,15 | F28: ='Сверка цен'!G28 | G28: 1 | H28: =D28*F28*G28 | I28: =D28*'Сверка цен'!E28*G28 | J28: =D28*'Сверка цен'!F28*G28
A29: 25 | B29: Щебень гранитный крупный (80-120 нет; между 40-70 и 100-200) | C29: м³ | D29: 200 | E29: нижний слой основания | F29: ='Сверка цен'!G29 | G29: 1 | H29: =D29*F29*G29 | I29: =D29*'Сверка цен'!E29*G29 | J29: =D29*'Сверка цен'!F29*G29
A30: 26 | B30: Щебень 20-40 | C30: м³ | D30: 650 | E30: основания 4100 м² × 0,15 | F30: ='Сверка цен'!G30 | G30: 1 | H30: =D30*F30*G30 | I30: =D30*'Сверка цен'!E30*G30 | J30: =D30*'Сверка цен'!F30*G30
A31: 27 | B31: Грунт растительный (навал с доставкой) | C31: м³ | D31: 750 | E31: газон 5000 м² × 0,15 | F31: ='Сверка цен'!G31 | G31: 1 | H31: =D31*F31*G31 | I31: =D31*'Сверка цен'!E31*G31 | J31: =D31*'Сверка цен'!F31*G31
A32: 28 | B32: Вода техническая (водовоз) | C32: м³ | D32: 200 | F32: ='Сверка цен'!G32 | G32: 1 | H32: =D32*F32*G32 | I32: =D32*'Сверка цен'!E32*G32 | J32: =D32*'Сверка цен'!F32*G32
A33: 29 | B33: Асфальтобетон горячий тип А/Б (ЩМА ~8 500–9 000) | C33: т | D33: 120 | E33: 1000 м² × 5 см | F33: ='Сверка цен'!G33 | G33: 1 | H33: =D33*F33*G33 | I33: =D33*'Сверка цен'!E33*G33 | J33: =D33*'Сверка цен'!F33*G33
A34: 30 | B34: Катанка 6,3–6,5 мм | C34: т | D34: 2 | F34: ='Сверка цен'!G34 | G34: 1 | H34: =D34*F34*G34 | I34: =D34*'Сверка цен'!E34*G34 | J34: =D34*'Сверка цен'!F34*G34
A35: 31 | B35: Лес круглый хвойный ø14–24 | C35: м³ | D35: 10 | F35: ='Сверка цен'!G35 | G35: 1 | H35: =D35*F35*G35 | I35: =D35*'Сверка цен'!E35*G35 | J35: =D35*'Сверка цен'!F35*G35
A36: 32 | B36: Брусок обрезной хвоя 1–2 с. | C36: м³ | D36: 5 | F36: ='Сверка цен'!G36 | G36: 1 | H36: =D36*F36*G36 | I36: =D36*'Сверка цен'!E36*G36 | J36: =D36*'Сверка цен'!F36*G36
A37: 33 | B37: Доска обрезная 25 мм | C37: м³ | D37: 10 | E37: опалубка | F37: ='Сверка цен'!G37 | G37: 1 | H37: =D37*F37*G37 | I37: =D37*'Сверка цен'!E37*G37 | J37: =D37*'Сверка цен'!F37*G37
A38: 34 | B38: Геотекстиль 300 г/м² | C38: м² | D38: 4500 | F38: ='Сверка цен'!G38 | G38: 1 | H38: =D38*F38*G38 | I38: =D38*'Сверка цен'!E38*G38 | J38: =D38*'Сверка цен'!F38*G38
A39: 35 | B39: Камень бутовый 150–500 мм | C39: т | D39: 50 | F39: ='Сверка цен'!G39 | G39: 1 | H39: =D39*F39*G39 | I39: =D39*'Сверка цен'!E39*G39 | J39: =D39*'Сверка цен'!F39*G39
A40: 36 | B40: Плёнка ПЭ 200 мкм (500 мкм ≈ 60–90) | C40: м² | D40: 1000 | F40: ='Сверка цен'!G40 | G40: 1 | H40: =D40*F40*G40 | I40: =D40*'Сверка цен'!E40*G40 | J40: =D40*'Сверка цен'!F40*G40
...

Sheet Риски и допущения
B1: ДОПУЩЕНИЯ
B2: В исходной смете нет количеств — итог посчитан по сценарию бульвара (лист «Сценарий»), объёмы условные.
B3: Каток 30 т в Хабаровске в аренду не найден — взяты грунтовые 16–20 т (поз. 15).
B4: Bobcat S630 — по аналогам S300/643/Барнаулец (поз. 4). Тягач 15 т — по тралам 30–65 т (поз. 8).
B5: Месячная аренда техники — расчёт 22 смены × ставка со скидкой 5–10%; прямых месячных предложений почти нет.
B6: Щебень фр. 80-120 у Корфовского карьера отсутствует — интерполяция между 40-70 и 100-200 (поз. 25).
B7: Асфальт — единственный публичный прайс АБЗ от 30.04.2025, индексирован на 2026 (+4–8%) (поз. 29).
B8: Бутовый камень — хабаровских цен нет, оценка по РФ + самосвал (поз. 35).
B9: Резиновая крошка, EPDM, связующее, пигменты — склады в центральной России, добавлена доставка ПЭК ~60 ₽/кг (поз. 37–40).
B10: Гранитная пиленая брусчатка 60 мм — в наличии в Хабаровске нет; цена РФ + ЖД-доставка отдельной строкой (поз. 46, 52). Альтернатива — местная колотая 2300–3400 ₽/м² или бетонная брусчатка.
B11: Цепное масло — федеральная розница (поз. 23). Пескобетон — аналог Старатели/RB, «Мастер Гарц» в Хабаровске нет (поз. 42).
B12: РИСКИ
... B24: Все цены собраны 20.10.2026 из открытых источников; ссылки — на листе «Сверка цен».
